INFO:root:====================
INFO:root:Cas: 2024-06-19 05:24:29 - START
INFO:root:Cas: 2024-06-19 05:25:00 - STOP
INFO:root:====================
INFO:root:Cas: 2024-06-19 05:25:53 - START
ERROR:root:An exception was thrown!
Traceback (most recent call last):
  File "C:\Users\Petr\AppData\Roaming\QGIS\QGIS3\profiles\default\python\plugins\qgis-convertshpgen4-plugin\creating_Gen4.py", line 933, in create_file
    output_folder, output_log = gen4_from_shp.creat_setup_xml()
                                ^^^^^^^^^^^^^^^^^^^^^^^^^^^^^^^
  File "C:\Users\Petr\AppData\Roaming\QGIS\QGIS3\profiles\default\python\plugins\qgis-convertshpgen4-plugin\creating_Gen4.py", line 452, in creat_setup_xml
    self.create_geojson_boundary(path_boundary, x_row['geometry'])
  File "C:\Users\Petr\AppData\Roaming\QGIS\QGIS3\profiles\default\python\plugins\qgis-convertshpgen4-plugin\creating_Gen4.py", line 582, in create_geojson_boundary
    with open(os.path.join(self.fold_spatial, path_boundary), 'w', encoding='UTF-8') as j:
         ^^^^^^^^^^^^^^^^^^^^^^^^^^^^^^^^^^^^^^^^^^^^^^^^^^^^^^^^^^^^^^^^^^^^^^^^^^^
FileNotFoundError: [Errno 2] No such file or directory: 'D:/Documents/Vyzkum/JD_Geo4/_LinkedId/JD data\\Gen4\\SpatialFiles\\Boundary56e5fbd4-b6ee-5da7-9c80-c1062af1836a.gjson'
INFO:root:Cas: 2024-06-19 05:26:50 - STOP
INFO:root:====================
INFO:root:Cas: 2024-06-19 05:27:02 - START
INFO:root:Cas: 2024-06-19 05:55:02 - STOP
INFO:root:====================
INFO:root:Cas: 2024-06-19 06:06:20 - START
INFO:root:Cas: 2024-06-19 06:34:05 - STOP
